2022-08-11 09:32:29,667  * Running on http://127.0.0.1:5000/ (Press CTRL+C to quit)
2022-08-11 09:32:45,170 127.0.0.1 - - [11/Aug/2022 09:32:45] "GET / HTTP/1.1" 200 -
2022-08-11 09:32:45,335 127.0.0.1 - - [11/Aug/2022 09:32:45] "GET /static/logo.png HTTP/1.1" 200 -
2022-08-11 09:32:46,275 127.0.0.1 - - [11/Aug/2022 09:32:46] "[33mGET /favicon.ico HTTP/1.1[0m" 404 -
2022-08-11 09:33:48,096 127.0.0.1 - - [11/Aug/2022 09:33:48] "[35m[1mGET /scans HTTP/1.1[0m" 500 -
2022-08-11 09:33:48,253 Error on request:
Traceback (most recent call last):
  File "C:\Users\CDL-Segun\AppData\Roaming\Python\Python39\site-packages\werkzeug\serving.py", line 319, in run_wsgi
    execute(self.server.app)
  File "C:\Users\CDL-Segun\AppData\Roaming\Python\Python39\site-packages\werkzeug\serving.py", line 308, in execute
    application_iter = app(environ, start_response)
  File "C:\Program Files\Python39\Lib\site-packages\flask\app.py", line 2091, in __call__
    return self.wsgi_app(environ, start_response)
  File "C:\Program Files\Python39\Lib\site-packages\flask\app.py", line 2076, in wsgi_app
    response = self.handle_exception(e)
  File "C:\Program Files\Python39\Lib\site-packages\flask\app.py", line 2073, in wsgi_app
    response = self.full_dispatch_request()
  File "C:\Program Files\Python39\Lib\site-packages\flask\app.py", line 1519, in full_dispatch_request
    return self.finalize_request(rv)
  File "C:\Program Files\Python39\Lib\site-packages\flask\app.py", line 1538, in finalize_request
    response = self.make_response(rv)
  File "C:\Program Files\Python39\Lib\site-packages\flask\app.py", line 1716, in make_response
    rv = jsonify(rv)
  File "C:\Program Files\Python39\Lib\site-packages\flask\json\__init__.py", line 361, in jsonify
    f"{dumps(data, indent=indent, separators=separators)}\n",
  File "C:\Program Files\Python39\Lib\site-packages\flask\json\__init__.py", line 139, in dumps
    rv = _json.dumps(obj, **kwargs)
  File "C:\Program Files\Python39\Lib\json\__init__.py", line 234, in dumps
    return cls(
  File "C:\Program Files\Python39\Lib\json\encoder.py", line 199, in encode
    chunks = self.iterencode(o, _one_shot=True)
  File "C:\Program Files\Python39\Lib\json\encoder.py", line 257, in iterencode
    return _iterencode(o, 0)
  File "C:\Program Files\Python39\Lib\site-packages\flask\json\__init__.py", line 57, in default
    return super().default(o)
  File "C:\Program Files\Python39\Lib\json\encoder.py", line 179, in default
    raise TypeError(f'Object of type {o.__class__.__name__} '
TypeError: Object of type BaseQuery is not JSON serializable
2022-08-11 09:36:58,704  * Running on http://127.0.0.1:5000/ (Press CTRL+C to quit)
2022-08-11 09:37:23,806 127.0.0.1 - - [11/Aug/2022 09:37:23] "[35m[1mGET /scans HTTP/1.1[0m" 500 -
2022-08-11 09:37:24,231 Error on request:
Traceback (most recent call last):
  File "src\pymssql\_pymssql.pyx", line 646, in pymssql._pymssql.connect
    
  File "src\pymssql\_mssql.pyx", line 2106, in pymssql._mssql.connect
    
  File "src\pymssql\_mssql.pyx", line 698, in pymssql._mssql.MSSQLConnection.__init__
    
  File "src\pymssql\_mssql.pyx", line 1815, in pymssql._mssql.maybe_raise_MSSQLDatabaseException
    
  File "src\pymssql\_mssql.pyx", line 1832, in pymssql._mssql.raise_MSSQLDatabaseException
    
pymssql._mssql.MSSQLDatabaseException: (20009, b'DB-Lib error message 20009, severity 9:\nUnable to connect: Adaptive Server is unavailable or does not exist (172.24.32.210)\nNet-Lib error during Unknown error (10060)\nDB-Lib error message 20009, severity 9:\nUnable to connect: Adaptive Server is unavailable or does not exist (172.24.32.210)\nNet-Lib error during Unknown error (10060)\n')

During handling of the above exception, another exception occurred:

Traceback (most recent call last):
  File "C:\Program Files\Python39\Lib\site-packages\sqlalchemy\engine\base.py", line 2345, in _wrap_pool_connect
    return fn()
  File "C:\Program Files\Python39\Lib\site-packages\sqlalchemy\pool\base.py", line 364, in connect
    return _ConnectionFairy._checkout(self)
  File "C:\Program Files\Python39\Lib\site-packages\sqlalchemy\pool\base.py", line 778, in _checkout
    fairy = _ConnectionRecord.checkout(pool)
  File "C:\Program Files\Python39\Lib\site-packages\sqlalchemy\pool\base.py", line 495, in checkout
    rec = pool._do_get()
  File "C:\Program Files\Python39\Lib\site-packages\sqlalchemy\pool\impl.py", line 140, in _do_get
    self._dec_overflow()
  File "C:\Program Files\Python39\Lib\site-packages\sqlalchemy\util\langhelpers.py", line 68, in __exit__
    compat.raise_(
  File "C:\Program Files\Python39\Lib\site-packages\sqlalchemy\util\compat.py", line 178, in raise_
    raise exception
  File "C:\Program Files\Python39\Lib\site-packages\sqlalchemy\pool\impl.py", line 137, in _do_get
    return self._create_connection()
  File "C:\Program Files\Python39\Lib\site-packages\sqlalchemy\pool\base.py", line 309, in _create_connection
    return _ConnectionRecord(self)
  File "C:\Program Files\Python39\Lib\site-packages\sqlalchemy\pool\base.py", line 440, in __init__
    self.__connect(first_connect_check=True)
  File "C:\Program Files\Python39\Lib\site-packages\sqlalchemy\pool\base.py", line 661, in __connect
    pool.logger.debug("Error on connect(): %s", e)
  File "C:\Program Files\Python39\Lib\site-packages\sqlalchemy\util\langhelpers.py", line 68, in __exit__
    compat.raise_(
  File "C:\Program Files\Python39\Lib\site-packages\sqlalchemy\util\compat.py", line 178, in raise_
    raise exception
  File "C:\Program Files\Python39\Lib\site-packages\sqlalchemy\pool\base.py", line 656, in __connect
    connection = pool._invoke_creator(self)
  File "C:\Program Files\Python39\Lib\site-packages\sqlalchemy\engine\strategies.py", line 114, in connect
    return dialect.connect(*cargs, **cparams)
  File "C:\Program Files\Python39\Lib\site-packages\sqlalchemy\engine\default.py", line 490, in connect
    return self.dbapi.connect(*cargs, **cparams)
  File "src\pymssql\_pymssql.pyx", line 652, in pymssql._pymssql.connect
    
pymssql._pymssql.OperationalError: (20009, b'DB-Lib error message 20009, severity 9:\nUnable to connect: Adaptive Server is unavailable or does not exist (172.24.32.210)\nNet-Lib error during Unknown error (10060)\nDB-Lib error message 20009, severity 9:\nUnable to connect: Adaptive Server is unavailable or does not exist (172.24.32.210)\nNet-Lib error during Unknown error (10060)\n')

The above exception was the direct cause of the following exception:

Traceback (most recent call last):
  File "C:\Users\CDL-Segun\AppData\Roaming\Python\Python39\site-packages\werkzeug\serving.py", line 319, in run_wsgi
    execute(self.server.app)
  File "C:\Users\CDL-Segun\AppData\Roaming\Python\Python39\site-packages\werkzeug\serving.py", line 308, in execute
    application_iter = app(environ, start_response)
  File "C:\Program Files\Python39\Lib\site-packages\flask\app.py", line 2091, in __call__
    return self.wsgi_app(environ, start_response)
  File "C:\Program Files\Python39\Lib\site-packages\flask\app.py", line 2076, in wsgi_app
    response = self.handle_exception(e)
  File "C:\Program Files\Python39\Lib\site-packages\flask\app.py", line 2073, in wsgi_app
    response = self.full_dispatch_request()
  File "C:\Program Files\Python39\Lib\site-packages\flask\app.py", line 1518, in full_dispatch_request
    rv = self.handle_user_exception(e)
  File "C:\Program Files\Python39\Lib\site-packages\flask\app.py", line 1516, in full_dispatch_request
    rv = self.dispatch_request()
  File "C:\Program Files\Python39\Lib\site-packages\flask\app.py", line 1502, in dispatch_request
    return self.ensure_sync(self.view_functions[rule.endpoint])(**req.view_args)
  File "C:\Users\CDL-Segun\Documents\Projects\CDL_PROD\CDL-OrderCleanup\ordercleanup\main\routes.py", line 96, in test_scans
    return {'result': get_orderscans()}
  File "C:\Users\CDL-Segun\Documents\Projects\CDL_PROD\CDL-OrderCleanup\ordercleanup\api_func\cleanup.py", line 45, in get_orderscans
    return order_scans.all()
  File "C:\Program Files\Python39\Lib\site-packages\sqlalchemy\orm\query.py", line 3319, in all
    return list(self)
  File "C:\Program Files\Python39\Lib\site-packages\sqlalchemy\orm\query.py", line 3481, in __iter__
    return self._execute_and_instances(context)
  File "C:\Program Files\Python39\Lib\site-packages\sqlalchemy\orm\query.py", line 3502, in _execute_and_instances
    conn = self._get_bind_args(
  File "C:\Program Files\Python39\Lib\site-packages\sqlalchemy\orm\query.py", line 3517, in _get_bind_args
    return fn(
  File "C:\Program Files\Python39\Lib\site-packages\sqlalchemy\orm\query.py", line 3496, in _connection_from_session
    conn = self.session.connection(**kw)
  File "C:\Program Files\Python39\Lib\site-packages\sqlalchemy\orm\session.py", line 1138, in connection
    return self._connection_for_bind(
  File "C:\Program Files\Python39\Lib\site-packages\sqlalchemy\orm\session.py", line 1146, in _connection_for_bind
    return self.transaction._connection_for_bind(
  File "C:\Program Files\Python39\Lib\site-packages\sqlalchemy\orm\session.py", line 433, in _connection_for_bind
    conn = bind._contextual_connect()
  File "C:\Program Files\Python39\Lib\site-packages\sqlalchemy\engine\base.py", line 2311, in _contextual_connect
    self._wrap_pool_connect(self.pool.connect, None),
  File "C:\Program Files\Python39\Lib\site-packages\sqlalchemy\engine\base.py", line 2348, in _wrap_pool_connect
    Connection._handle_dbapi_exception_noconnection(
  File "C:\Program Files\Python39\Lib\site-packages\sqlalchemy\engine\base.py", line 1590, in _handle_dbapi_exception_noconnection
    util.raise_(
  File "C:\Program Files\Python39\Lib\site-packages\sqlalchemy\util\compat.py", line 178, in raise_
    raise exception
  File "C:\Program Files\Python39\Lib\site-packages\sqlalchemy\engine\base.py", line 2345, in _wrap_pool_connect
    return fn()
  File "C:\Program Files\Python39\Lib\site-packages\sqlalchemy\pool\base.py", line 364, in connect
    return _ConnectionFairy._checkout(self)
  File "C:\Program Files\Python39\Lib\site-packages\sqlalchemy\pool\base.py", line 778, in _checkout
    fairy = _ConnectionRecord.checkout(pool)
  File "C:\Program Files\Python39\Lib\site-packages\sqlalchemy\pool\base.py", line 495, in checkout
    rec = pool._do_get()
  File "C:\Program Files\Python39\Lib\site-packages\sqlalchemy\pool\impl.py", line 140, in _do_get
    self._dec_overflow()
  File "C:\Program Files\Python39\Lib\site-packages\sqlalchemy\util\langhelpers.py", line 68, in __exit__
    compat.raise_(
  File "C:\Program Files\Python39\Lib\site-packages\sqlalchemy\util\compat.py", line 178, in raise_
    raise exception
  File "C:\Program Files\Python39\Lib\site-packages\sqlalchemy\pool\impl.py", line 137, in _do_get
    return self._create_connection()
  File "C:\Program Files\Python39\Lib\site-packages\sqlalchemy\pool\base.py", line 309, in _create_connection
    return _ConnectionRecord(self)
  File "C:\Program Files\Python39\Lib\site-packages\sqlalchemy\pool\base.py", line 440, in __init__
    self.__connect(first_connect_check=True)
  File "C:\Program Files\Python39\Lib\site-packages\sqlalchemy\pool\base.py", line 661, in __connect
    pool.logger.debug("Error on connect(): %s", e)
  File "C:\Program Files\Python39\Lib\site-packages\sqlalchemy\util\langhelpers.py", line 68, in __exit__
    compat.raise_(
  File "C:\Program Files\Python39\Lib\site-packages\sqlalchemy\util\compat.py", line 178, in raise_
    raise exception
  File "C:\Program Files\Python39\Lib\site-packages\sqlalchemy\pool\base.py", line 656, in __connect
    connection = pool._invoke_creator(self)
  File "C:\Program Files\Python39\Lib\site-packages\sqlalchemy\engine\strategies.py", line 114, in connect
    return dialect.connect(*cargs, **cparams)
  File "C:\Program Files\Python39\Lib\site-packages\sqlalchemy\engine\default.py", line 490, in connect
    return self.dbapi.connect(*cargs, **cparams)
  File "src\pymssql\_pymssql.pyx", line 652, in pymssql._pymssql.connect
    
sqlalchemy.exc.OperationalError: (pymssql._pymssql.OperationalError) (20009, b'DB-Lib error message 20009, severity 9:\nUnable to connect: Adaptive Server is unavailable or does not exist (172.24.32.210)\nNet-Lib error during Unknown error (10060)\nDB-Lib error message 20009, severity 9:\nUnable to connect: Adaptive Server is unavailable or does not exist (172.24.32.210)\nNet-Lib error during Unknown error (10060)\n')
(Background on this error at: http://sqlalche.me/e/e3q8)
2022-08-11 10:15:30,584  * Running on http://127.0.0.1:5000/ (Press CTRL+C to quit)
2022-08-11 10:16:45,872 127.0.0.1 - - [11/Aug/2022 10:16:45] "GET /test HTTP/1.1" 200 -
2022-08-11 10:17:56,369  * Running on http://127.0.0.1:5000/ (Press CTRL+C to quit)
2022-08-11 10:18:03,422 127.0.0.1 - - [11/Aug/2022 10:18:03] "GET /test HTTP/1.1" 200 -
